[2024-11-10T23:47:48.038+0000] {local_task_job_runner.py:123} INFO - ::group::Pre task execution logs
[2024-11-10T23:47:48.159+0000] {taskinstance.py:2613} INFO - Dependencies all met for dep_context=non-requeueable deps ti=<TaskInstance: api_inserir_dadosH.create_table_historico_precos manual__2024-11-10T23:47:36.594598+00:00 [queued]>
[2024-11-10T23:47:48.215+0000] {taskinstance.py:2613} INFO - Dependencies all met for dep_context=requeueable deps ti=<TaskInstance: api_inserir_dadosH.create_table_historico_precos manual__2024-11-10T23:47:36.594598+00:00 [queued]>
[2024-11-10T23:47:48.216+0000] {taskinstance.py:2866} INFO - Starting attempt 1 of 2
[2024-11-10T23:47:48.235+0000] {taskinstance.py:2889} INFO - Executing <Task(PostgresOperator): create_table_historico_precos> on 2024-11-10 23:47:36.594598+00:00
[2024-11-10T23:47:48.245+0000] {warnings.py:112} WARNING - /home/***/.local/lib/python3.12/site-packages/***/task/task_runner/standard_task_runner.py:70: DeprecationWarning: This process (pid=271) is multi-threaded, use of fork() may lead to deadlocks in the child.
  pid = os.fork()

[2024-11-10T23:47:48.247+0000] {standard_task_runner.py:72} INFO - Started process 273 to run task
[2024-11-10T23:47:48.247+0000] {standard_task_runner.py:104} INFO - Running: ['***', 'tasks', 'run', 'api_inserir_dadosH', 'create_table_historico_precos', 'manual__2024-11-10T23:47:36.594598+00:00', '--job-id', '5', '--raw', '--subdir', 'DAGS_FOLDER/etl.py', '--cfg-path', '/tmp/tmprw8fq6t4']
[2024-11-10T23:47:48.248+0000] {standard_task_runner.py:105} INFO - Job 5: Subtask create_table_historico_precos
[2024-11-10T23:47:48.291+0000] {task_command.py:467} INFO - Running <TaskInstance: api_inserir_dadosH.create_table_historico_precos manual__2024-11-10T23:47:36.594598+00:00 [running]> on host 39a50528ad78
[2024-11-10T23:47:48.364+0000] {taskinstance.py:3132} INFO - Exporting env vars: AIRFLOW_CTX_DAG_OWNER='***' AIRFLOW_CTX_DAG_ID='api_inserir_dadosH' AIRFLOW_CTX_TASK_ID='create_table_historico_precos' AIRFLOW_CTX_EXECUTION_DATE='2024-11-10T23:47:36.594598+00:00' AIRFLOW_CTX_TRY_NUMBER='1' AIRFLOW_CTX_DAG_RUN_ID='manual__2024-11-10T23:47:36.594598+00:00'
[2024-11-10T23:47:48.365+0000] {logging_mixin.py:190} INFO - Task instance is in running state
[2024-11-10T23:47:48.365+0000] {logging_mixin.py:190} INFO -  Previous state of the Task instance: queued
[2024-11-10T23:47:48.365+0000] {logging_mixin.py:190} INFO - Current task name:create_table_historico_precos state:running start_date:2024-11-10 23:47:48.161575+00:00
[2024-11-10T23:47:48.365+0000] {logging_mixin.py:190} INFO - Dag name:api_inserir_dadosH and current dag run status:running
[2024-11-10T23:47:48.365+0000] {taskinstance.py:731} INFO - ::endgroup::
[2024-11-10T23:47:48.366+0000] {sql.py:278} INFO - Executing: 
CREATE TABLE IF NOT EXISTS historico_precos (
    id INT,
    name VARCHAR(10),
    date TIMESTAMP,
    open DECIMAL(10, 2),
    high DECIMAL(10, 2),
    low DECIMAL(10, 2),
    close DECIMAL(10, 2),
    volume BIGINT,
    adjusted_close DECIMAL(10, 2),
    FOREIGN KEY (id) REFERENCES summary_profile(id)
);
[2024-11-10T23:47:48.376+0000] {base.py:84} INFO - Retrieving connection 'postgres-***'
[2024-11-10T23:47:48.388+0000] {base.py:84} INFO - Retrieving connection 'postgres-***'
[2024-11-10T23:47:48.392+0000] {sql.py:544} INFO - Running statement: 
CREATE TABLE IF NOT EXISTS historico_precos (
    id INT,
    name VARCHAR(10),
    date TIMESTAMP,
    open DECIMAL(10, 2),
    high DECIMAL(10, 2),
    low DECIMAL(10, 2),
    close DECIMAL(10, 2),
    volume BIGINT,
    adjusted_close DECIMAL(10, 2),
    FOREIGN KEY (id) REFERENCES summary_profile(id)
);, parameters: None
[2024-11-10T23:47:48.395+0000] {taskinstance.py:3311} ERROR - Task failed with exception
Traceback (most recent call last):
  File "/home/airflow/.local/lib/python3.12/site-packages/airflow/models/taskinstance.py", line 767, in _execute_task
    result = _execute_callable(context=context, **execute_callable_kwargs)
             ^^^^^^^^^^^^^^^^^^^^^^^^^^^^^^^^^^^^^^^^^^^^^^^^^^^^^^^^^^^^^
  File "/home/airflow/.local/lib/python3.12/site-packages/airflow/models/taskinstance.py", line 733, in _execute_callable
    return ExecutionCallableRunner(
           ^^^^^^^^^^^^^^^^^^^^^^^^
  File "/home/airflow/.local/lib/python3.12/site-packages/airflow/utils/operator_helpers.py", line 252, in run
    return self.func(*args, **kwargs)
           ^^^^^^^^^^^^^^^^^^^^^^^^^^
  File "/home/airflow/.local/lib/python3.12/site-packages/airflow/models/baseoperator.py", line 417, in wrapper
    return func(self, *args, **kwargs)
           ^^^^^^^^^^^^^^^^^^^^^^^^^^^
  File "/home/airflow/.local/lib/python3.12/site-packages/airflow/providers/common/sql/operators/sql.py", line 284, in execute
    output = hook.run(
             ^^^^^^^^^
  File "/home/airflow/.local/lib/python3.12/site-packages/airflow/providers/common/sql/hooks/sql.py", line 489, in run
    self._run_command(cur, sql_statement, parameters)
  File "/home/airflow/.local/lib/python3.12/site-packages/airflow/providers/common/sql/hooks/sql.py", line 549, in _run_command
    cur.execute(sql_statement)
psycopg2.errors.UndefinedTable: relation "summary_profile" does not exist

[2024-11-10T23:47:48.408+0000] {logging_mixin.py:190} INFO - Task instance in failure state
[2024-11-10T23:47:48.408+0000] {logging_mixin.py:190} INFO - Task start:2024-11-10 23:47:48.161575+00:00 end:2024-11-10 23:47:48.407597+00:00 duration:0.246022
[2024-11-10T23:47:48.408+0000] {logging_mixin.py:190} INFO - Task:<Task(PostgresOperator): create_table_historico_precos> dag:<DAG: api_inserir_dadosH> dagrun:<DagRun api_inserir_dadosH @ 2024-11-10 23:47:36.594598+00:00: manual__2024-11-10T23:47:36.594598+00:00, state:running, queued_at: 2024-11-10 23:47:36.619325+00:00. externally triggered: True>
[2024-11-10T23:47:48.408+0000] {logging_mixin.py:190} INFO - Failure caused by relation "summary_profile" does not exist
[2024-11-10T23:47:48.408+0000] {taskinstance.py:1225} INFO - Marking task as UP_FOR_RETRY. dag_id=api_inserir_dadosH, task_id=create_table_historico_precos, run_id=manual__2024-11-10T23:47:36.594598+00:00, execution_date=20241110T234736, start_date=20241110T234748, end_date=20241110T234748
[2024-11-10T23:47:48.423+0000] {taskinstance.py:340} INFO - ::group::Post task execution logs
[2024-11-10T23:47:48.424+0000] {standard_task_runner.py:124} ERROR - Failed to execute job 5 for task create_table_historico_precos (relation "summary_profile" does not exist
; 273)
Traceback (most recent call last):
  File "/home/airflow/.local/lib/python3.12/site-packages/airflow/task/task_runner/standard_task_runner.py", line 117, in _start_by_fork
    ret = args.func(args, dag=self.dag)
          ^^^^^^^^^^^^^^^^^^^^^^^^^^^^^
  File "/home/airflow/.local/lib/python3.12/site-packages/airflow/cli/cli_config.py", line 49, in command
    return func(*args, **kwargs)
           ^^^^^^^^^^^^^^^^^^^^^
  File "/home/airflow/.local/lib/python3.12/site-packages/airflow/utils/cli.py", line 116, in wrapper
    return f(*args, **kwargs)
           ^^^^^^^^^^^^^^^^^^
  File "/home/airflow/.local/lib/python3.12/site-packages/airflow/cli/commands/task_command.py", line 483, in task_run
    task_return_code = _run_task_by_selected_method(args, _dag, ti)
                       ^^^^^^^^^^^^^^^^^^^^^^^^^^^^^^^^^^^^^^^^^^^^
  File "/home/airflow/.local/lib/python3.12/site-packages/airflow/cli/commands/task_command.py", line 256, in _run_task_by_selected_method
    return _run_raw_task(args, ti)
           ^^^^^^^^^^^^^^^^^^^^^^^
  File "/home/airflow/.local/lib/python3.12/site-packages/airflow/cli/commands/task_command.py", line 341, in _run_raw_task
    return ti._run_raw_task(
           ^^^^^^^^^^^^^^^^^
  File "/home/airflow/.local/lib/python3.12/site-packages/airflow/utils/session.py", line 97, in wrapper
    return func(*args, session=session, **kwargs)
           ^^^^^^^^^^^^^^^^^^^^^^^^^^^^^^^^^^^^^^
  File "/home/airflow/.local/lib/python3.12/site-packages/airflow/models/taskinstance.py", line 3005, in _run_raw_task
    return _run_raw_task(
           ^^^^^^^^^^^^^^
  File "/home/airflow/.local/lib/python3.12/site-packages/airflow/models/taskinstance.py", line 273, in _run_raw_task
    TaskInstance._execute_task_with_callbacks(
  File "/home/airflow/.local/lib/python3.12/site-packages/airflow/models/taskinstance.py", line 3159, in _execute_task_with_callbacks
    result = self._execute_task(context, task_orig)
             ^^^^^^^^^^^^^^^^^^^^^^^^^^^^^^^^^^^^^^
  File "/home/airflow/.local/lib/python3.12/site-packages/airflow/models/taskinstance.py", line 3183, in _execute_task
    return _execute_task(self, context, task_orig)
           ^^^^^^^^^^^^^^^^^^^^^^^^^^^^^^^^^^^^^^^
  File "/home/airflow/.local/lib/python3.12/site-packages/airflow/models/taskinstance.py", line 767, in _execute_task
    result = _execute_callable(context=context, **execute_callable_kwargs)
             ^^^^^^^^^^^^^^^^^^^^^^^^^^^^^^^^^^^^^^^^^^^^^^^^^^^^^^^^^^^^^
  File "/home/airflow/.local/lib/python3.12/site-packages/airflow/models/taskinstance.py", line 733, in _execute_callable
    return ExecutionCallableRunner(
           ^^^^^^^^^^^^^^^^^^^^^^^^
  File "/home/airflow/.local/lib/python3.12/site-packages/airflow/utils/operator_helpers.py", line 252, in run
    return self.func(*args, **kwargs)
           ^^^^^^^^^^^^^^^^^^^^^^^^^^
  File "/home/airflow/.local/lib/python3.12/site-packages/airflow/models/baseoperator.py", line 417, in wrapper
    return func(self, *args, **kwargs)
           ^^^^^^^^^^^^^^^^^^^^^^^^^^^
  File "/home/airflow/.local/lib/python3.12/site-packages/airflow/providers/common/sql/operators/sql.py", line 284, in execute
    output = hook.run(
             ^^^^^^^^^
  File "/home/airflow/.local/lib/python3.12/site-packages/airflow/providers/common/sql/hooks/sql.py", line 489, in run
    self._run_command(cur, sql_statement, parameters)
  File "/home/airflow/.local/lib/python3.12/site-packages/airflow/providers/common/sql/hooks/sql.py", line 549, in _run_command
    cur.execute(sql_statement)
psycopg2.errors.UndefinedTable: relation "summary_profile" does not exist

[2024-11-10T23:47:48.461+0000] {local_task_job_runner.py:266} INFO - Task exited with return code 1
[2024-11-10T23:47:48.825+0000] {taskinstance.py:3895} INFO - 0 downstream tasks scheduled from follow-on schedule check
[2024-11-10T23:47:48.826+0000] {local_task_job_runner.py:245} INFO - ::endgroup::
