[2024-11-16T21:53:44.322+0000] {local_task_job_runner.py:123} INFO - ::group::Pre task execution logs
[2024-11-16T21:53:44.350+0000] {taskinstance.py:2613} INFO - Dependencies all met for dep_context=non-requeueable deps ti=<TaskInstance: criar_tabelas.inserir_dados_historico manual__2024-11-16T21:53:39.941631+00:00 [queued]>
[2024-11-16T21:53:44.366+0000] {taskinstance.py:2613} INFO - Dependencies all met for dep_context=requeueable deps ti=<TaskInstance: criar_tabelas.inserir_dados_historico manual__2024-11-16T21:53:39.941631+00:00 [queued]>
[2024-11-16T21:53:44.366+0000] {taskinstance.py:2866} INFO - Starting attempt 1 of 2
[2024-11-16T21:53:44.429+0000] {taskinstance.py:2889} INFO - Executing <Task(PythonOperator): inserir_dados_historico> on 2024-11-16 21:53:39.941631+00:00
[2024-11-16T21:53:44.464+0000] {warnings.py:112} WARNING - /home/***/.local/lib/python3.12/site-packages/***/task/task_runner/standard_task_runner.py:70: DeprecationWarning: This process (pid=308) is multi-threaded, use of fork() may lead to deadlocks in the child.
  pid = os.fork()

[2024-11-16T21:53:44.468+0000] {standard_task_runner.py:72} INFO - Started process 312 to run task
[2024-11-16T21:53:44.470+0000] {standard_task_runner.py:104} INFO - Running: ['***', 'tasks', 'run', 'criar_tabelas', 'inserir_dados_historico', 'manual__2024-11-16T21:53:39.941631+00:00', '--job-id', '33', '--raw', '--subdir', 'DAGS_FOLDER/etl.py', '--cfg-path', '/tmp/tmp2mg680vo']
[2024-11-16T21:53:44.472+0000] {standard_task_runner.py:105} INFO - Job 33: Subtask inserir_dados_historico
[2024-11-16T21:53:44.583+0000] {task_command.py:467} INFO - Running <TaskInstance: criar_tabelas.inserir_dados_historico manual__2024-11-16T21:53:39.941631+00:00 [running]> on host 7766afd0bc11
[2024-11-16T21:53:45.292+0000] {taskinstance.py:3132} INFO - Exporting env vars: AIRFLOW_CTX_DAG_OWNER='***' AIRFLOW_CTX_DAG_ID='criar_tabelas' AIRFLOW_CTX_TASK_ID='inserir_dados_historico' AIRFLOW_CTX_EXECUTION_DATE='2024-11-16T21:53:39.941631+00:00' AIRFLOW_CTX_TRY_NUMBER='1' AIRFLOW_CTX_DAG_RUN_ID='manual__2024-11-16T21:53:39.941631+00:00'
[2024-11-16T21:53:45.298+0000] {logging_mixin.py:190} INFO - Task instance is in running state
[2024-11-16T21:53:45.298+0000] {logging_mixin.py:190} INFO -  Previous state of the Task instance: queued
[2024-11-16T21:53:45.299+0000] {logging_mixin.py:190} INFO - Current task name:inserir_dados_historico state:running start_date:2024-11-16 21:53:44.350877+00:00
[2024-11-16T21:53:45.299+0000] {logging_mixin.py:190} INFO - Dag name:criar_tabelas and current dag run status:running
[2024-11-16T21:53:45.299+0000] {taskinstance.py:731} INFO - ::endgroup::
[2024-11-16T21:53:55.466+0000] {taskinstance.py:3311} ERROR - Task failed with exception
Traceback (most recent call last):
  File "/home/airflow/.local/lib/python3.12/site-packages/urllib3/connection.py", line 199, in _new_conn
    sock = connection.create_connection(
           ^^^^^^^^^^^^^^^^^^^^^^^^^^^^^
  File "/home/airflow/.local/lib/python3.12/site-packages/urllib3/util/connection.py", line 60, in create_connection
    for res in socket.getaddrinfo(host, port, family, socket.SOCK_STREAM):
               ^^^^^^^^^^^^^^^^^^^^^^^^^^^^^^^^^^^^^^^^^^^^^^^^^^^^^^^^^^
  File "/usr/local/lib/python3.12/socket.py", line 976, in getaddrinfo
    for res in _socket.getaddrinfo(host, port, family, type, proto, flags):
               ^^^^^^^^^^^^^^^^^^^^^^^^^^^^^^^^^^^^^^^^^^^^^^^^^^^^^^^^^^^
socket.gaierror: [Errno -3] Temporary failure in name resolution

The above exception was the direct cause of the following exception:

Traceback (most recent call last):
  File "/home/airflow/.local/lib/python3.12/site-packages/urllib3/connectionpool.py", line 789, in urlopen
    response = self._make_request(
               ^^^^^^^^^^^^^^^^^^^
  File "/home/airflow/.local/lib/python3.12/site-packages/urllib3/connectionpool.py", line 490, in _make_request
    raise new_e
  File "/home/airflow/.local/lib/python3.12/site-packages/urllib3/connectionpool.py", line 466, in _make_request
    self._validate_conn(conn)
  File "/home/airflow/.local/lib/python3.12/site-packages/urllib3/connectionpool.py", line 1095, in _validate_conn
    conn.connect()
  File "/home/airflow/.local/lib/python3.12/site-packages/urllib3/connection.py", line 693, in connect
    self.sock = sock = self._new_conn()
                       ^^^^^^^^^^^^^^^^
  File "/home/airflow/.local/lib/python3.12/site-packages/urllib3/connection.py", line 206, in _new_conn
    raise NameResolutionError(self.host, self, e) from e
urllib3.exceptions.NameResolutionError: <urllib3.connection.HTTPSConnection object at 0x74bc95207ec0>: Failed to resolve 'brapi.dev' ([Errno -3] Temporary failure in name resolution)

The above exception was the direct cause of the following exception:

Traceback (most recent call last):
  File "/home/airflow/.local/lib/python3.12/site-packages/requests/adapters.py", line 667, in send
    resp = conn.urlopen(
           ^^^^^^^^^^^^^
  File "/home/airflow/.local/lib/python3.12/site-packages/urllib3/connectionpool.py", line 843, in urlopen
    retries = retries.increment(
              ^^^^^^^^^^^^^^^^^^
  File "/home/airflow/.local/lib/python3.12/site-packages/urllib3/util/retry.py", line 519, in increment
    raise MaxRetryError(_pool, url, reason) from reason  # type: ignore[arg-type]
    ^^^^^^^^^^^^^^^^^^^^^^^^^^^^^^^^^^^^^^^^^^^^^^^^^^^
urllib3.exceptions.MaxRetryError: HTTPSConnectionPool(host='brapi.dev', port=443): Max retries exceeded with url: /api/quote/PETR4,%5EBVSP?range=5y&interval=1d&dividends=true&token=nyvMfdacbcxr6kSDu8nfM1 (Caused by NameResolutionError("<urllib3.connection.HTTPSConnection object at 0x74bc95207ec0>: Failed to resolve 'brapi.dev' ([Errno -3] Temporary failure in name resolution)"))

During handling of the above exception, another exception occurred:

Traceback (most recent call last):
  File "/home/airflow/.local/lib/python3.12/site-packages/airflow/models/taskinstance.py", line 767, in _execute_task
    result = _execute_callable(context=context, **execute_callable_kwargs)
             ^^^^^^^^^^^^^^^^^^^^^^^^^^^^^^^^^^^^^^^^^^^^^^^^^^^^^^^^^^^^^
  File "/home/airflow/.local/lib/python3.12/site-packages/airflow/models/taskinstance.py", line 733, in _execute_callable
    return ExecutionCallableRunner(
           ^^^^^^^^^^^^^^^^^^^^^^^^
  File "/home/airflow/.local/lib/python3.12/site-packages/airflow/utils/operator_helpers.py", line 252, in run
    return self.func(*args, **kwargs)
           ^^^^^^^^^^^^^^^^^^^^^^^^^^
  File "/home/airflow/.local/lib/python3.12/site-packages/airflow/models/baseoperator.py", line 417, in wrapper
    return func(self, *args, **kwargs)
           ^^^^^^^^^^^^^^^^^^^^^^^^^^^
  File "/home/airflow/.local/lib/python3.12/site-packages/airflow/operators/python.py", line 238, in execute
    return_value = self.execute_callable()
                   ^^^^^^^^^^^^^^^^^^^^^^^
  File "/home/airflow/.local/lib/python3.12/site-packages/airflow/operators/python.py", line 256, in execute_callable
    return runner.run(*self.op_args, **self.op_kwargs)
           ^^^^^^^^^^^^^^^^^^^^^^^^^^^^^^^^^^^^^^^^^^^
  File "/home/airflow/.local/lib/python3.12/site-packages/airflow/utils/operator_helpers.py", line 252, in run
    return self.func(*args, **kwargs)
           ^^^^^^^^^^^^^^^^^^^^^^^^^^
  File "/opt/airflow/dags/etl.py", line 240, in inserir_dados_historico
    response = requests.get(url, params=params)
               ^^^^^^^^^^^^^^^^^^^^^^^^^^^^^^^^
  File "/home/airflow/.local/lib/python3.12/site-packages/requests/api.py", line 73, in get
    return request("get", url, params=params, **kwargs)
           ^^^^^^^^^^^^^^^^^^^^^^^^^^^^^^^^^^^^^^^^^^^^
  File "/home/airflow/.local/lib/python3.12/site-packages/requests/api.py", line 59, in request
    return session.request(method=method, url=url, **kwargs)
           ^^^^^^^^^^^^^^^^^^^^^^^^^^^^^^^^^^^^^^^^^^^^^^^^^
  File "/home/airflow/.local/lib/python3.12/site-packages/requests/sessions.py", line 589, in request
    resp = self.send(prep, **send_kwargs)
           ^^^^^^^^^^^^^^^^^^^^^^^^^^^^^^
  File "/home/airflow/.local/lib/python3.12/site-packages/requests/sessions.py", line 703, in send
    r = adapter.send(request, **kwargs)
        ^^^^^^^^^^^^^^^^^^^^^^^^^^^^^^^
  File "/home/airflow/.local/lib/python3.12/site-packages/requests/adapters.py", line 700, in send
    raise ConnectionError(e, request=request)
requests.exceptions.ConnectionError: HTTPSConnectionPool(host='brapi.dev', port=443): Max retries exceeded with url: /api/quote/PETR4,%5EBVSP?range=5y&interval=1d&dividends=true&token=nyvMfdacbcxr6kSDu8nfM1 (Caused by NameResolutionError("<urllib3.connection.HTTPSConnection object at 0x74bc95207ec0>: Failed to resolve 'brapi.dev' ([Errno -3] Temporary failure in name resolution)"))
[2024-11-16T21:54:06.480+0000] {taskinstance.py:340} INFO - ::group::Post task execution logs
