[2024-11-17T01:31:46.518+0000] {local_task_job_runner.py:123} INFO - ::group::Pre task execution logs
[2024-11-17T01:31:46.537+0000] {taskinstance.py:2613} INFO - Dependencies all met for dep_context=non-requeueable deps ti=<TaskInstance: criar_tabelas.create_ETL manual__2024-11-17T01:28:59.417195+00:00 [queued]>
[2024-11-17T01:31:46.545+0000] {taskinstance.py:2613} INFO - Dependencies all met for dep_context=requeueable deps ti=<TaskInstance: criar_tabelas.create_ETL manual__2024-11-17T01:28:59.417195+00:00 [queued]>
[2024-11-17T01:31:46.545+0000] {taskinstance.py:2866} INFO - Starting attempt 2 of 2
[2024-11-17T01:31:46.557+0000] {taskinstance.py:2889} INFO - Executing <Task(PostgresOperator): create_ETL> on 2024-11-17 01:28:59.417195+00:00
[2024-11-17T01:31:46.569+0000] {warnings.py:112} WARNING - /home/***/.local/lib/python3.12/site-packages/***/task/task_runner/standard_task_runner.py:70: DeprecationWarning: This process (pid=142) is multi-threaded, use of fork() may lead to deadlocks in the child.
  pid = os.fork()

[2024-11-17T01:31:46.571+0000] {standard_task_runner.py:72} INFO - Started process 145 to run task
[2024-11-17T01:31:46.571+0000] {standard_task_runner.py:104} INFO - Running: ['***', 'tasks', 'run', 'criar_tabelas', 'create_ETL', 'manual__2024-11-17T01:28:59.417195+00:00', '--job-id', '10', '--raw', '--subdir', 'DAGS_FOLDER/etl.py', '--cfg-path', '/tmp/tmpgfqyzm7z']
[2024-11-17T01:31:46.572+0000] {standard_task_runner.py:105} INFO - Job 10: Subtask create_ETL
[2024-11-17T01:31:46.618+0000] {task_command.py:467} INFO - Running <TaskInstance: criar_tabelas.create_ETL manual__2024-11-17T01:28:59.417195+00:00 [running]> on host bfeda1f9cf11
[2024-11-17T01:31:46.976+0000] {taskinstance.py:3132} INFO - Exporting env vars: AIRFLOW_CTX_DAG_OWNER='***' AIRFLOW_CTX_DAG_ID='criar_tabelas' AIRFLOW_CTX_TASK_ID='create_ETL' AIRFLOW_CTX_EXECUTION_DATE='2024-11-17T01:28:59.417195+00:00' AIRFLOW_CTX_TRY_NUMBER='2' AIRFLOW_CTX_DAG_RUN_ID='manual__2024-11-17T01:28:59.417195+00:00'
[2024-11-17T01:31:46.977+0000] {logging_mixin.py:190} INFO - Task instance is in running state
[2024-11-17T01:31:46.977+0000] {logging_mixin.py:190} INFO -  Previous state of the Task instance: queued
[2024-11-17T01:31:46.977+0000] {logging_mixin.py:190} INFO - Current task name:create_ETL state:running start_date:2024-11-17 01:31:46.537743+00:00
[2024-11-17T01:31:46.977+0000] {logging_mixin.py:190} INFO - Dag name:criar_tabelas and current dag run status:running
[2024-11-17T01:31:46.977+0000] {taskinstance.py:731} INFO - ::endgroup::
[2024-11-17T01:31:46.977+0000] {sql.py:278} INFO - Executing: 
CREATE database ETL;

[2024-11-17T01:31:46.987+0000] {base.py:84} INFO - Retrieving connection 'postgres-***'
[2024-11-17T01:31:47.002+0000] {base.py:84} INFO - Retrieving connection 'postgres-***'
[2024-11-17T01:31:47.007+0000] {sql.py:544} INFO - Running statement: 
CREATE database ETL;
, parameters: None
[2024-11-17T01:31:47.009+0000] {taskinstance.py:3311} ERROR - Task failed with exception
Traceback (most recent call last):
  File "/home/airflow/.local/lib/python3.12/site-packages/airflow/models/taskinstance.py", line 767, in _execute_task
    result = _execute_callable(context=context, **execute_callable_kwargs)
             ^^^^^^^^^^^^^^^^^^^^^^^^^^^^^^^^^^^^^^^^^^^^^^^^^^^^^^^^^^^^^
  File "/home/airflow/.local/lib/python3.12/site-packages/airflow/models/taskinstance.py", line 733, in _execute_callable
    return ExecutionCallableRunner(
           ^^^^^^^^^^^^^^^^^^^^^^^^
  File "/home/airflow/.local/lib/python3.12/site-packages/airflow/utils/operator_helpers.py", line 252, in run
    return self.func(*args, **kwargs)
           ^^^^^^^^^^^^^^^^^^^^^^^^^^
  File "/home/airflow/.local/lib/python3.12/site-packages/airflow/models/baseoperator.py", line 417, in wrapper
    return func(self, *args, **kwargs)
           ^^^^^^^^^^^^^^^^^^^^^^^^^^^
  File "/home/airflow/.local/lib/python3.12/site-packages/airflow/providers/common/sql/operators/sql.py", line 284, in execute
    output = hook.run(
             ^^^^^^^^^
  File "/home/airflow/.local/lib/python3.12/site-packages/airflow/providers/common/sql/hooks/sql.py", line 489, in run
    self._run_command(cur, sql_statement, parameters)
  File "/home/airflow/.local/lib/python3.12/site-packages/airflow/providers/common/sql/hooks/sql.py", line 549, in _run_command
    cur.execute(sql_statement)
psycopg2.errors.ActiveSqlTransaction: CREATE DATABASE cannot run inside a transaction block

[2024-11-17T01:31:47.024+0000] {logging_mixin.py:190} INFO - Task instance in failure state
[2024-11-17T01:31:47.025+0000] {logging_mixin.py:190} INFO - Task start:2024-11-17 01:31:46.537743+00:00 end:2024-11-17 01:31:47.024552+00:00 duration:0.486809
[2024-11-17T01:31:47.025+0000] {logging_mixin.py:190} INFO - Task:<Task(PostgresOperator): create_ETL> dag:<DAG: criar_tabelas> dagrun:<DagRun criar_tabelas @ 2024-11-17 01:28:59.417195+00:00: manual__2024-11-17T01:28:59.417195+00:00, state:running, queued_at: 2024-11-17 01:28:59.442598+00:00. externally triggered: True>
[2024-11-17T01:31:47.025+0000] {logging_mixin.py:190} INFO - Failure caused by CREATE DATABASE cannot run inside a transaction block
[2024-11-17T01:31:47.025+0000] {taskinstance.py:1225} INFO - Marking task as FAILED. dag_id=criar_tabelas, task_id=create_ETL, run_id=manual__2024-11-17T01:28:59.417195+00:00, execution_date=20241117T012859, start_date=20241117T013146, end_date=20241117T013147
[2024-11-17T01:31:47.036+0000] {taskinstance.py:340} INFO - ::group::Post task execution logs
[2024-11-17T01:31:47.037+0000] {standard_task_runner.py:124} ERROR - Failed to execute job 10 for task create_ETL (CREATE DATABASE cannot run inside a transaction block
; 145)
Traceback (most recent call last):
  File "/home/airflow/.local/lib/python3.12/site-packages/airflow/task/task_runner/standard_task_runner.py", line 117, in _start_by_fork
    ret = args.func(args, dag=self.dag)
          ^^^^^^^^^^^^^^^^^^^^^^^^^^^^^
  File "/home/airflow/.local/lib/python3.12/site-packages/airflow/cli/cli_config.py", line 49, in command
    return func(*args, **kwargs)
           ^^^^^^^^^^^^^^^^^^^^^
  File "/home/airflow/.local/lib/python3.12/site-packages/airflow/utils/cli.py", line 116, in wrapper
    return f(*args, **kwargs)
           ^^^^^^^^^^^^^^^^^^
  File "/home/airflow/.local/lib/python3.12/site-packages/airflow/cli/commands/task_command.py", line 483, in task_run
    task_return_code = _run_task_by_selected_method(args, _dag, ti)
                       ^^^^^^^^^^^^^^^^^^^^^^^^^^^^^^^^^^^^^^^^^^^^
  File "/home/airflow/.local/lib/python3.12/site-packages/airflow/cli/commands/task_command.py", line 256, in _run_task_by_selected_method
    return _run_raw_task(args, ti)
           ^^^^^^^^^^^^^^^^^^^^^^^
  File "/home/airflow/.local/lib/python3.12/site-packages/airflow/cli/commands/task_command.py", line 341, in _run_raw_task
    return ti._run_raw_task(
           ^^^^^^^^^^^^^^^^^
  File "/home/airflow/.local/lib/python3.12/site-packages/airflow/utils/session.py", line 97, in wrapper
    return func(*args, session=session, **kwargs)
           ^^^^^^^^^^^^^^^^^^^^^^^^^^^^^^^^^^^^^^
  File "/home/airflow/.local/lib/python3.12/site-packages/airflow/models/taskinstance.py", line 3005, in _run_raw_task
    return _run_raw_task(
           ^^^^^^^^^^^^^^
  File "/home/airflow/.local/lib/python3.12/site-packages/airflow/models/taskinstance.py", line 273, in _run_raw_task
    TaskInstance._execute_task_with_callbacks(
  File "/home/airflow/.local/lib/python3.12/site-packages/airflow/models/taskinstance.py", line 3159, in _execute_task_with_callbacks
    result = self._execute_task(context, task_orig)
             ^^^^^^^^^^^^^^^^^^^^^^^^^^^^^^^^^^^^^^
  File "/home/airflow/.local/lib/python3.12/site-packages/airflow/models/taskinstance.py", line 3183, in _execute_task
    return _execute_task(self, context, task_orig)
           ^^^^^^^^^^^^^^^^^^^^^^^^^^^^^^^^^^^^^^^
  File "/home/airflow/.local/lib/python3.12/site-packages/airflow/models/taskinstance.py", line 767, in _execute_task
    result = _execute_callable(context=context, **execute_callable_kwargs)
             ^^^^^^^^^^^^^^^^^^^^^^^^^^^^^^^^^^^^^^^^^^^^^^^^^^^^^^^^^^^^^
  File "/home/airflow/.local/lib/python3.12/site-packages/airflow/models/taskinstance.py", line 733, in _execute_callable
    return ExecutionCallableRunner(
           ^^^^^^^^^^^^^^^^^^^^^^^^
  File "/home/airflow/.local/lib/python3.12/site-packages/airflow/utils/operator_helpers.py", line 252, in run
    return self.func(*args, **kwargs)
           ^^^^^^^^^^^^^^^^^^^^^^^^^^
  File "/home/airflow/.local/lib/python3.12/site-packages/airflow/models/baseoperator.py", line 417, in wrapper
    return func(self, *args, **kwargs)
           ^^^^^^^^^^^^^^^^^^^^^^^^^^^
  File "/home/airflow/.local/lib/python3.12/site-packages/airflow/providers/common/sql/operators/sql.py", line 284, in execute
    output = hook.run(
             ^^^^^^^^^
  File "/home/airflow/.local/lib/python3.12/site-packages/airflow/providers/common/sql/hooks/sql.py", line 489, in run
    self._run_command(cur, sql_statement, parameters)
  File "/home/airflow/.local/lib/python3.12/site-packages/airflow/providers/common/sql/hooks/sql.py", line 549, in _run_command
    cur.execute(sql_statement)
psycopg2.errors.ActiveSqlTransaction: CREATE DATABASE cannot run inside a transaction block

[2024-11-17T01:31:47.106+0000] {local_task_job_runner.py:266} INFO - Task exited with return code 1
[2024-11-17T01:31:47.133+0000] {taskinstance.py:3895} INFO - 0 downstream tasks scheduled from follow-on schedule check
[2024-11-17T01:31:47.137+0000] {local_task_job_runner.py:245} INFO - ::endgroup::
