[2024-11-08T22:53:07.791+0000] {local_task_job_runner.py:123} INFO - ::group::Pre task execution logs
[2024-11-08T22:53:07.808+0000] {taskinstance.py:2613} INFO - Dependencies all met for dep_context=non-requeueable deps ti=<TaskInstance: api_inserir_dadosH.inserir_dados_historico manual__2024-11-08T22:48:02.686933+00:00 [queued]>
[2024-11-08T22:53:07.815+0000] {taskinstance.py:2613} INFO - Dependencies all met for dep_context=requeueable deps ti=<TaskInstance: api_inserir_dadosH.inserir_dados_historico manual__2024-11-08T22:48:02.686933+00:00 [queued]>
[2024-11-08T22:53:07.815+0000] {taskinstance.py:2866} INFO - Starting attempt 2 of 2
[2024-11-08T22:53:07.826+0000] {taskinstance.py:2889} INFO - Executing <Task(PythonOperator): inserir_dados_historico> on 2024-11-08 22:48:02.686933+00:00
[2024-11-08T22:53:07.837+0000] {warnings.py:112} WARNING - /home/***/.local/lib/python3.12/site-packages/***/task/task_runner/standard_task_runner.py:70: DeprecationWarning: This process (pid=639) is multi-threaded, use of fork() may lead to deadlocks in the child.
  pid = os.fork()

[2024-11-08T22:53:07.838+0000] {standard_task_runner.py:72} INFO - Started process 641 to run task
[2024-11-08T22:53:07.839+0000] {standard_task_runner.py:104} INFO - Running: ['***', 'tasks', 'run', 'api_inserir_dadosH', 'inserir_dados_historico', 'manual__2024-11-08T22:48:02.686933+00:00', '--job-id', '8', '--raw', '--subdir', 'DAGS_FOLDER/etl.py', '--cfg-path', '/tmp/tmpp2_2hp9z']
[2024-11-08T22:53:07.840+0000] {standard_task_runner.py:105} INFO - Job 8: Subtask inserir_dados_historico
[2024-11-08T22:53:07.884+0000] {task_command.py:467} INFO - Running <TaskInstance: api_inserir_dadosH.inserir_dados_historico manual__2024-11-08T22:48:02.686933+00:00 [running]> on host b1539bc96044
[2024-11-08T22:53:07.957+0000] {taskinstance.py:3132} INFO - Exporting env vars: AIRFLOW_CTX_DAG_OWNER='***' AIRFLOW_CTX_DAG_ID='api_inserir_dadosH' AIRFLOW_CTX_TASK_ID='inserir_dados_historico' AIRFLOW_CTX_EXECUTION_DATE='2024-11-08T22:48:02.686933+00:00' AIRFLOW_CTX_TRY_NUMBER='2' AIRFLOW_CTX_DAG_RUN_ID='manual__2024-11-08T22:48:02.686933+00:00'
[2024-11-08T22:53:07.958+0000] {logging_mixin.py:190} INFO - Task instance is in running state
[2024-11-08T22:53:07.958+0000] {logging_mixin.py:190} INFO -  Previous state of the Task instance: queued
[2024-11-08T22:53:07.958+0000] {logging_mixin.py:190} INFO - Current task name:inserir_dados_historico state:running start_date:2024-11-08 22:53:07.808368+00:00
[2024-11-08T22:53:07.959+0000] {logging_mixin.py:190} INFO - Dag name:api_inserir_dadosH and current dag run status:running
[2024-11-08T22:53:07.959+0000] {taskinstance.py:731} INFO - ::endgroup::
[2024-11-08T22:53:08.043+0000] {taskinstance.py:3311} ERROR - Task failed with exception
Traceback (most recent call last):
  File "/home/airflow/.local/lib/python3.12/site-packages/mysql/connector/connection_cext.py", line 335, in _open_connection
    self._cmysql.connect(**cnx_kwargs)
_mysql_connector.MySQLInterfaceError: Can't connect to MySQL server on 'localhost:3306' (99)

The above exception was the direct cause of the following exception:

Traceback (most recent call last):
  File "/home/airflow/.local/lib/python3.12/site-packages/airflow/models/taskinstance.py", line 767, in _execute_task
    result = _execute_callable(context=context, **execute_callable_kwargs)
             ^^^^^^^^^^^^^^^^^^^^^^^^^^^^^^^^^^^^^^^^^^^^^^^^^^^^^^^^^^^^^
  File "/home/airflow/.local/lib/python3.12/site-packages/airflow/models/taskinstance.py", line 733, in _execute_callable
    return ExecutionCallableRunner(
           ^^^^^^^^^^^^^^^^^^^^^^^^
  File "/home/airflow/.local/lib/python3.12/site-packages/airflow/utils/operator_helpers.py", line 252, in run
    return self.func(*args, **kwargs)
           ^^^^^^^^^^^^^^^^^^^^^^^^^^
  File "/home/airflow/.local/lib/python3.12/site-packages/airflow/models/baseoperator.py", line 417, in wrapper
    return func(self, *args, **kwargs)
           ^^^^^^^^^^^^^^^^^^^^^^^^^^^
  File "/home/airflow/.local/lib/python3.12/site-packages/airflow/operators/python.py", line 238, in execute
    return_value = self.execute_callable()
                   ^^^^^^^^^^^^^^^^^^^^^^^
  File "/home/airflow/.local/lib/python3.12/site-packages/airflow/operators/python.py", line 256, in execute_callable
    return runner.run(*self.op_args, **self.op_kwargs)
           ^^^^^^^^^^^^^^^^^^^^^^^^^^^^^^^^^^^^^^^^^^^
  File "/home/airflow/.local/lib/python3.12/site-packages/airflow/utils/operator_helpers.py", line 252, in run
    return self.func(*args, **kwargs)
           ^^^^^^^^^^^^^^^^^^^^^^^^^^
  File "/opt/airflow/dags/etl.py", line 21, in inserir_dados_historico
    conn = mysql.connector.connect(
           ^^^^^^^^^^^^^^^^^^^^^^^^
  File "/home/airflow/.local/lib/python3.12/site-packages/mysql/connector/pooling.py", line 322, in connect
    return CMySQLConnection(*args, **kwargs)
           ^^^^^^^^^^^^^^^^^^^^^^^^^^^^^^^^^
  File "/home/airflow/.local/lib/python3.12/site-packages/mysql/connector/connection_cext.py", line 151, in __init__
    self.connect(**kwargs)
  File "/home/airflow/.local/lib/python3.12/site-packages/mysql/connector/abstracts.py", line 1426, in connect
    self._open_connection()
  File "/home/airflow/.local/lib/python3.12/site-packages/mysql/connector/connection_cext.py", line 340, in _open_connection
    raise get_mysql_exception(
mysql.connector.errors.DatabaseError: 2003 (HY000): Can't connect to MySQL server on 'localhost:3306' (99)
[2024-11-08T22:53:08.056+0000] {logging_mixin.py:190} INFO - Task instance in failure state
[2024-11-08T22:53:08.057+0000] {logging_mixin.py:190} INFO - Task start:2024-11-08 22:53:07.808368+00:00 end:2024-11-08 22:53:08.056331+00:00 duration:0.247963
[2024-11-08T22:53:08.057+0000] {logging_mixin.py:190} INFO - Task:<Task(PythonOperator): inserir_dados_historico> dag:<DAG: api_inserir_dadosH> dagrun:<DagRun api_inserir_dadosH @ 2024-11-08 22:48:02.686933+00:00: manual__2024-11-08T22:48:02.686933+00:00, state:running, queued_at: 2024-11-08 22:48:02.707920+00:00. externally triggered: True>
[2024-11-08T22:53:08.057+0000] {logging_mixin.py:190} INFO - Failure caused by 2003 (HY000): Can't connect to MySQL server on 'localhost:3306' (99)
[2024-11-08T22:53:08.057+0000] {taskinstance.py:1225} INFO - Marking task as FAILED. dag_id=api_inserir_dadosH, task_id=inserir_dados_historico, run_id=manual__2024-11-08T22:48:02.686933+00:00, execution_date=20241108T224802, start_date=20241108T225307, end_date=20241108T225308
[2024-11-08T22:53:08.067+0000] {taskinstance.py:340} INFO - ::group::Post task execution logs
[2024-11-08T22:53:08.067+0000] {standard_task_runner.py:124} ERROR - Failed to execute job 8 for task inserir_dados_historico (2003 (HY000): Can't connect to MySQL server on 'localhost:3306' (99); 641)
Traceback (most recent call last):
  File "/home/airflow/.local/lib/python3.12/site-packages/mysql/connector/connection_cext.py", line 335, in _open_connection
    self._cmysql.connect(**cnx_kwargs)
_mysql_connector.MySQLInterfaceError: Can't connect to MySQL server on 'localhost:3306' (99)

The above exception was the direct cause of the following exception:

Traceback (most recent call last):
  File "/home/airflow/.local/lib/python3.12/site-packages/airflow/task/task_runner/standard_task_runner.py", line 117, in _start_by_fork
    ret = args.func(args, dag=self.dag)
          ^^^^^^^^^^^^^^^^^^^^^^^^^^^^^
  File "/home/airflow/.local/lib/python3.12/site-packages/airflow/cli/cli_config.py", line 49, in command
    return func(*args, **kwargs)
           ^^^^^^^^^^^^^^^^^^^^^
  File "/home/airflow/.local/lib/python3.12/site-packages/airflow/utils/cli.py", line 116, in wrapper
    return f(*args, **kwargs)
           ^^^^^^^^^^^^^^^^^^
  File "/home/airflow/.local/lib/python3.12/site-packages/airflow/cli/commands/task_command.py", line 483, in task_run
    task_return_code = _run_task_by_selected_method(args, _dag, ti)
                       ^^^^^^^^^^^^^^^^^^^^^^^^^^^^^^^^^^^^^^^^^^^^
  File "/home/airflow/.local/lib/python3.12/site-packages/airflow/cli/commands/task_command.py", line 256, in _run_task_by_selected_method
    return _run_raw_task(args, ti)
           ^^^^^^^^^^^^^^^^^^^^^^^
  File "/home/airflow/.local/lib/python3.12/site-packages/airflow/cli/commands/task_command.py", line 341, in _run_raw_task
    return ti._run_raw_task(
           ^^^^^^^^^^^^^^^^^
  File "/home/airflow/.local/lib/python3.12/site-packages/airflow/utils/session.py", line 97, in wrapper
    return func(*args, session=session, **kwargs)
           ^^^^^^^^^^^^^^^^^^^^^^^^^^^^^^^^^^^^^^
  File "/home/airflow/.local/lib/python3.12/site-packages/airflow/models/taskinstance.py", line 3005, in _run_raw_task
    return _run_raw_task(
           ^^^^^^^^^^^^^^
  File "/home/airflow/.local/lib/python3.12/site-packages/airflow/models/taskinstance.py", line 273, in _run_raw_task
    TaskInstance._execute_task_with_callbacks(
  File "/home/airflow/.local/lib/python3.12/site-packages/airflow/models/taskinstance.py", line 3159, in _execute_task_with_callbacks
    result = self._execute_task(context, task_orig)
             ^^^^^^^^^^^^^^^^^^^^^^^^^^^^^^^^^^^^^^
  File "/home/airflow/.local/lib/python3.12/site-packages/airflow/models/taskinstance.py", line 3183, in _execute_task
    return _execute_task(self, context, task_orig)
           ^^^^^^^^^^^^^^^^^^^^^^^^^^^^^^^^^^^^^^^
  File "/home/airflow/.local/lib/python3.12/site-packages/airflow/models/taskinstance.py", line 767, in _execute_task
    result = _execute_callable(context=context, **execute_callable_kwargs)
             ^^^^^^^^^^^^^^^^^^^^^^^^^^^^^^^^^^^^^^^^^^^^^^^^^^^^^^^^^^^^^
  File "/home/airflow/.local/lib/python3.12/site-packages/airflow/models/taskinstance.py", line 733, in _execute_callable
    return ExecutionCallableRunner(
           ^^^^^^^^^^^^^^^^^^^^^^^^
  File "/home/airflow/.local/lib/python3.12/site-packages/airflow/utils/operator_helpers.py", line 252, in run
    return self.func(*args, **kwargs)
           ^^^^^^^^^^^^^^^^^^^^^^^^^^
  File "/home/airflow/.local/lib/python3.12/site-packages/airflow/models/baseoperator.py", line 417, in wrapper
    return func(self, *args, **kwargs)
           ^^^^^^^^^^^^^^^^^^^^^^^^^^^
  File "/home/airflow/.local/lib/python3.12/site-packages/airflow/operators/python.py", line 238, in execute
    return_value = self.execute_callable()
                   ^^^^^^^^^^^^^^^^^^^^^^^
  File "/home/airflow/.local/lib/python3.12/site-packages/airflow/operators/python.py", line 256, in execute_callable
    return runner.run(*self.op_args, **self.op_kwargs)
           ^^^^^^^^^^^^^^^^^^^^^^^^^^^^^^^^^^^^^^^^^^^
  File "/home/airflow/.local/lib/python3.12/site-packages/airflow/utils/operator_helpers.py", line 252, in run
    return self.func(*args, **kwargs)
           ^^^^^^^^^^^^^^^^^^^^^^^^^^
  File "/opt/airflow/dags/etl.py", line 21, in inserir_dados_historico
    conn = mysql.connector.connect(
           ^^^^^^^^^^^^^^^^^^^^^^^^
  File "/home/airflow/.local/lib/python3.12/site-packages/mysql/connector/pooling.py", line 322, in connect
    return CMySQLConnection(*args, **kwargs)
           ^^^^^^^^^^^^^^^^^^^^^^^^^^^^^^^^^
  File "/home/airflow/.local/lib/python3.12/site-packages/mysql/connector/connection_cext.py", line 151, in __init__
    self.connect(**kwargs)
  File "/home/airflow/.local/lib/python3.12/site-packages/mysql/connector/abstracts.py", line 1426, in connect
    self._open_connection()
  File "/home/airflow/.local/lib/python3.12/site-packages/mysql/connector/connection_cext.py", line 340, in _open_connection
    raise get_mysql_exception(
mysql.connector.errors.DatabaseError: 2003 (HY000): Can't connect to MySQL server on 'localhost:3306' (99)
[2024-11-08T22:53:08.093+0000] {local_task_job_runner.py:266} INFO - Task exited with return code 1
[2024-11-08T22:53:08.107+0000] {taskinstance.py:3895} INFO - 0 downstream tasks scheduled from follow-on schedule check
[2024-11-08T22:53:08.108+0000] {local_task_job_runner.py:245} INFO - ::endgroup::
