[2024-11-17T03:19:32.679+0000] {local_task_job_runner.py:123} INFO - ::group::Pre task execution logs
[2024-11-17T03:19:32.694+0000] {taskinstance.py:2613} INFO - Dependencies all met for dep_context=non-requeueable deps ti=<TaskInstance: criar_tabelas.inserir_dados_summary manual__2024-11-17T03:19:11.176694+00:00 [queued]>
[2024-11-17T03:19:32.702+0000] {taskinstance.py:2613} INFO - Dependencies all met for dep_context=requeueable deps ti=<TaskInstance: criar_tabelas.inserir_dados_summary manual__2024-11-17T03:19:11.176694+00:00 [queued]>
[2024-11-17T03:19:32.703+0000] {taskinstance.py:2866} INFO - Starting attempt 1 of 2
[2024-11-17T03:19:32.714+0000] {taskinstance.py:2889} INFO - Executing <Task(PythonOperator): inserir_dados_summary> on 2024-11-17 03:19:11.176694+00:00
[2024-11-17T03:19:32.724+0000] {warnings.py:112} WARNING - /home/***/.local/lib/python3.12/site-packages/***/task/task_runner/standard_task_runner.py:70: DeprecationWarning: This process (pid=815) is multi-threaded, use of fork() may lead to deadlocks in the child.
  pid = os.fork()

[2024-11-17T03:19:32.726+0000] {standard_task_runner.py:72} INFO - Started process 817 to run task
[2024-11-17T03:19:32.726+0000] {standard_task_runner.py:104} INFO - Running: ['***', 'tasks', 'run', 'criar_tabelas', 'inserir_dados_summary', 'manual__2024-11-17T03:19:11.176694+00:00', '--job-id', '242', '--raw', '--subdir', 'DAGS_FOLDER/etl.py', '--cfg-path', '/tmp/tmppwasbcy6']
[2024-11-17T03:19:32.727+0000] {standard_task_runner.py:105} INFO - Job 242: Subtask inserir_dados_summary
[2024-11-17T03:19:32.770+0000] {task_command.py:467} INFO - Running <TaskInstance: criar_tabelas.inserir_dados_summary manual__2024-11-17T03:19:11.176694+00:00 [running]> on host bfeda1f9cf11
[2024-11-17T03:19:33.045+0000] {taskinstance.py:3132} INFO - Exporting env vars: AIRFLOW_CTX_DAG_OWNER='***' AIRFLOW_CTX_DAG_ID='criar_tabelas' AIRFLOW_CTX_TASK_ID='inserir_dados_summary' AIRFLOW_CTX_EXECUTION_DATE='2024-11-17T03:19:11.176694+00:00' AIRFLOW_CTX_TRY_NUMBER='1' AIRFLOW_CTX_DAG_RUN_ID='manual__2024-11-17T03:19:11.176694+00:00'
[2024-11-17T03:19:33.046+0000] {logging_mixin.py:190} INFO - Task instance is in running state
[2024-11-17T03:19:33.046+0000] {logging_mixin.py:190} INFO -  Previous state of the Task instance: queued
[2024-11-17T03:19:33.047+0000] {logging_mixin.py:190} INFO - Current task name:inserir_dados_summary state:running start_date:2024-11-17 03:19:32.695133+00:00
[2024-11-17T03:19:33.047+0000] {logging_mixin.py:190} INFO - Dag name:criar_tabelas and current dag run status:running
[2024-11-17T03:19:33.047+0000] {taskinstance.py:731} INFO - ::endgroup::
[2024-11-17T03:19:33.152+0000] {taskinstance.py:3311} ERROR - Task failed with exception
Traceback (most recent call last):
  File "/home/airflow/.local/lib/python3.12/site-packages/airflow/models/taskinstance.py", line 767, in _execute_task
    result = _execute_callable(context=context, **execute_callable_kwargs)
             ^^^^^^^^^^^^^^^^^^^^^^^^^^^^^^^^^^^^^^^^^^^^^^^^^^^^^^^^^^^^^
  File "/home/airflow/.local/lib/python3.12/site-packages/airflow/models/taskinstance.py", line 733, in _execute_callable
    return ExecutionCallableRunner(
           ^^^^^^^^^^^^^^^^^^^^^^^^
  File "/home/airflow/.local/lib/python3.12/site-packages/airflow/utils/operator_helpers.py", line 252, in run
    return self.func(*args, **kwargs)
           ^^^^^^^^^^^^^^^^^^^^^^^^^^
  File "/home/airflow/.local/lib/python3.12/site-packages/airflow/models/baseoperator.py", line 417, in wrapper
    return func(self, *args, **kwargs)
           ^^^^^^^^^^^^^^^^^^^^^^^^^^^
  File "/home/airflow/.local/lib/python3.12/site-packages/airflow/operators/python.py", line 238, in execute
    return_value = self.execute_callable()
                   ^^^^^^^^^^^^^^^^^^^^^^^
  File "/home/airflow/.local/lib/python3.12/site-packages/airflow/operators/python.py", line 256, in execute_callable
    return runner.run(*self.op_args, **self.op_kwargs)
           ^^^^^^^^^^^^^^^^^^^^^^^^^^^^^^^^^^^^^^^^^^^
  File "/home/airflow/.local/lib/python3.12/site-packages/airflow/utils/operator_helpers.py", line 252, in run
    return self.func(*args, **kwargs)
           ^^^^^^^^^^^^^^^^^^^^^^^^^^
  File "/home/gabriel/workspace/airflow-docker/dags/etl.py", line 416, in inserir_dados_summary
    cursor.execute(insert_query, (
psycopg2.errors.UniqueViolation: duplicate key value violates unique constraint "summaryprofile_pkey"
DETAIL:  Key (id)=(1) already exists.

[2024-11-17T03:19:33.166+0000] {logging_mixin.py:190} INFO - Task instance in failure state
[2024-11-17T03:19:33.167+0000] {logging_mixin.py:190} INFO - Task start:2024-11-17 03:19:32.695133+00:00 end:2024-11-17 03:19:33.166569+00:00 duration:0.471436
[2024-11-17T03:19:33.167+0000] {logging_mixin.py:190} INFO - Task:<Task(PythonOperator): inserir_dados_summary> dag:<DAG: criar_tabelas> dagrun:<DagRun criar_tabelas @ 2024-11-17 03:19:11.176694+00:00: manual__2024-11-17T03:19:11.176694+00:00, state:running, queued_at: 2024-11-17 03:19:11.191640+00:00. externally triggered: True>
[2024-11-17T03:19:33.167+0000] {logging_mixin.py:190} INFO - Failure caused by duplicate key value violates unique constraint "summaryprofile_pkey"
DETAIL:  Key (id)=(1) already exists.
[2024-11-17T03:19:33.167+0000] {taskinstance.py:1225} INFO - Marking task as UP_FOR_RETRY. dag_id=criar_tabelas, task_id=inserir_dados_summary, run_id=manual__2024-11-17T03:19:11.176694+00:00, execution_date=20241117T031911, start_date=20241117T031932, end_date=20241117T031933
[2024-11-17T03:19:33.181+0000] {taskinstance.py:340} INFO - ::group::Post task execution logs
[2024-11-17T03:19:33.181+0000] {standard_task_runner.py:124} ERROR - Failed to execute job 242 for task inserir_dados_summary (duplicate key value violates unique constraint "summaryprofile_pkey"
DETAIL:  Key (id)=(1) already exists.
; 817)
Traceback (most recent call last):
  File "/home/airflow/.local/lib/python3.12/site-packages/airflow/task/task_runner/standard_task_runner.py", line 117, in _start_by_fork
    ret = args.func(args, dag=self.dag)
          ^^^^^^^^^^^^^^^^^^^^^^^^^^^^^
  File "/home/airflow/.local/lib/python3.12/site-packages/airflow/cli/cli_config.py", line 49, in command
    return func(*args, **kwargs)
           ^^^^^^^^^^^^^^^^^^^^^
  File "/home/airflow/.local/lib/python3.12/site-packages/airflow/utils/cli.py", line 116, in wrapper
    return f(*args, **kwargs)
           ^^^^^^^^^^^^^^^^^^
  File "/home/airflow/.local/lib/python3.12/site-packages/airflow/cli/commands/task_command.py", line 483, in task_run
    task_return_code = _run_task_by_selected_method(args, _dag, ti)
                       ^^^^^^^^^^^^^^^^^^^^^^^^^^^^^^^^^^^^^^^^^^^^
  File "/home/airflow/.local/lib/python3.12/site-packages/airflow/cli/commands/task_command.py", line 256, in _run_task_by_selected_method
    return _run_raw_task(args, ti)
           ^^^^^^^^^^^^^^^^^^^^^^^
  File "/home/airflow/.local/lib/python3.12/site-packages/airflow/cli/commands/task_command.py", line 341, in _run_raw_task
    return ti._run_raw_task(
           ^^^^^^^^^^^^^^^^^
  File "/home/airflow/.local/lib/python3.12/site-packages/airflow/utils/session.py", line 97, in wrapper
    return func(*args, session=session, **kwargs)
           ^^^^^^^^^^^^^^^^^^^^^^^^^^^^^^^^^^^^^^
  File "/home/airflow/.local/lib/python3.12/site-packages/airflow/models/taskinstance.py", line 3005, in _run_raw_task
    return _run_raw_task(
           ^^^^^^^^^^^^^^
  File "/home/airflow/.local/lib/python3.12/site-packages/airflow/models/taskinstance.py", line 273, in _run_raw_task
    TaskInstance._execute_task_with_callbacks(
  File "/home/airflow/.local/lib/python3.12/site-packages/airflow/models/taskinstance.py", line 3159, in _execute_task_with_callbacks
    result = self._execute_task(context, task_orig)
             ^^^^^^^^^^^^^^^^^^^^^^^^^^^^^^^^^^^^^^
  File "/home/airflow/.local/lib/python3.12/site-packages/airflow/models/taskinstance.py", line 3183, in _execute_task
    return _execute_task(self, context, task_orig)
           ^^^^^^^^^^^^^^^^^^^^^^^^^^^^^^^^^^^^^^^
  File "/home/airflow/.local/lib/python3.12/site-packages/airflow/models/taskinstance.py", line 767, in _execute_task
    result = _execute_callable(context=context, **execute_callable_kwargs)
             ^^^^^^^^^^^^^^^^^^^^^^^^^^^^^^^^^^^^^^^^^^^^^^^^^^^^^^^^^^^^^
  File "/home/airflow/.local/lib/python3.12/site-packages/airflow/models/taskinstance.py", line 733, in _execute_callable
    return ExecutionCallableRunner(
           ^^^^^^^^^^^^^^^^^^^^^^^^
  File "/home/airflow/.local/lib/python3.12/site-packages/airflow/utils/operator_helpers.py", line 252, in run
    return self.func(*args, **kwargs)
           ^^^^^^^^^^^^^^^^^^^^^^^^^^
  File "/home/airflow/.local/lib/python3.12/site-packages/airflow/models/baseoperator.py", line 417, in wrapper
    return func(self, *args, **kwargs)
           ^^^^^^^^^^^^^^^^^^^^^^^^^^^
  File "/home/airflow/.local/lib/python3.12/site-packages/airflow/operators/python.py", line 238, in execute
    return_value = self.execute_callable()
                   ^^^^^^^^^^^^^^^^^^^^^^^
  File "/home/airflow/.local/lib/python3.12/site-packages/airflow/operators/python.py", line 256, in execute_callable
    return runner.run(*self.op_args, **self.op_kwargs)
           ^^^^^^^^^^^^^^^^^^^^^^^^^^^^^^^^^^^^^^^^^^^
  File "/home/airflow/.local/lib/python3.12/site-packages/airflow/utils/operator_helpers.py", line 252, in run
    return self.func(*args, **kwargs)
           ^^^^^^^^^^^^^^^^^^^^^^^^^^
  File "/home/gabriel/workspace/airflow-docker/dags/etl.py", line 416, in inserir_dados_summary
    cursor.execute(insert_query, (
psycopg2.errors.UniqueViolation: duplicate key value violates unique constraint "summaryprofile_pkey"
DETAIL:  Key (id)=(1) already exists.

[2024-11-17T03:19:33.221+0000] {local_task_job_runner.py:266} INFO - Task exited with return code 1
[2024-11-17T03:19:33.242+0000] {taskinstance.py:3895} INFO - 0 downstream tasks scheduled from follow-on schedule check
[2024-11-17T03:19:33.243+0000] {local_task_job_runner.py:245} INFO - ::endgroup::
