[2024-11-08T22:46:29.033+0000] {local_task_job_runner.py:123} INFO - ::group::Pre task execution logs
[2024-11-08T22:46:29.053+0000] {taskinstance.py:2613} INFO - Dependencies all met for dep_context=non-requeueable deps ti=<TaskInstance: api_inserir_dadosH.inserir_dados_historico scheduled__2024-11-07T00:00:00+00:00 [queued]>
[2024-11-08T22:46:29.062+0000] {taskinstance.py:2613} INFO - Dependencies all met for dep_context=requeueable deps ti=<TaskInstance: api_inserir_dadosH.inserir_dados_historico scheduled__2024-11-07T00:00:00+00:00 [queued]>
[2024-11-08T22:46:29.062+0000] {taskinstance.py:2866} INFO - Starting attempt 1 of 2
[2024-11-08T22:46:29.075+0000] {taskinstance.py:2889} INFO - Executing <Task(PythonOperator): inserir_dados_historico> on 2024-11-07 00:00:00+00:00
[2024-11-08T22:46:29.086+0000] {warnings.py:112} WARNING - /home/***/.local/lib/python3.12/site-packages/***/task/task_runner/standard_task_runner.py:70: DeprecationWarning: This process (pid=544) is multi-threaded, use of fork() may lead to deadlocks in the child.
  pid = os.fork()

[2024-11-08T22:46:29.087+0000] {standard_task_runner.py:72} INFO - Started process 546 to run task
[2024-11-08T22:46:29.088+0000] {standard_task_runner.py:104} INFO - Running: ['***', 'tasks', 'run', 'api_inserir_dadosH', 'inserir_dados_historico', 'scheduled__2024-11-07T00:00:00+00:00', '--job-id', '5', '--raw', '--subdir', 'DAGS_FOLDER/etl.py', '--cfg-path', '/tmp/tmpoc749z1p']
[2024-11-08T22:46:29.089+0000] {standard_task_runner.py:105} INFO - Job 5: Subtask inserir_dados_historico
[2024-11-08T22:46:29.139+0000] {task_command.py:467} INFO - Running <TaskInstance: api_inserir_dadosH.inserir_dados_historico scheduled__2024-11-07T00:00:00+00:00 [running]> on host b1539bc96044
[2024-11-08T22:46:29.214+0000] {taskinstance.py:3132} INFO - Exporting env vars: AIRFLOW_CTX_DAG_OWNER='***' AIRFLOW_CTX_DAG_ID='api_inserir_dadosH' AIRFLOW_CTX_TASK_ID='inserir_dados_historico' AIRFLOW_CTX_EXECUTION_DATE='2024-11-07T00:00:00+00:00' AIRFLOW_CTX_TRY_NUMBER='1' AIRFLOW_CTX_DAG_RUN_ID='scheduled__2024-11-07T00:00:00+00:00'
[2024-11-08T22:46:29.215+0000] {logging_mixin.py:190} INFO - Task instance is in running state
[2024-11-08T22:46:29.216+0000] {logging_mixin.py:190} INFO -  Previous state of the Task instance: queued
[2024-11-08T22:46:29.216+0000] {logging_mixin.py:190} INFO - Current task name:inserir_dados_historico state:running start_date:2024-11-08 22:46:29.054104+00:00
[2024-11-08T22:46:29.216+0000] {logging_mixin.py:190} INFO - Dag name:api_inserir_dadosH and current dag run status:running
[2024-11-08T22:46:29.216+0000] {taskinstance.py:731} INFO - ::endgroup::
[2024-11-08T22:46:30.242+0000] {taskinstance.py:3311} ERROR - Task failed with exception
Traceback (most recent call last):
  File "/home/airflow/.local/lib/python3.12/site-packages/mysql/connector/connection_cext.py", line 335, in _open_connection
    self._cmysql.connect(**cnx_kwargs)
_mysql_connector.MySQLInterfaceError: Can't connect to MySQL server on 'localhost:3306' (99)

The above exception was the direct cause of the following exception:

Traceback (most recent call last):
  File "/home/airflow/.local/lib/python3.12/site-packages/airflow/models/taskinstance.py", line 767, in _execute_task
    result = _execute_callable(context=context, **execute_callable_kwargs)
             ^^^^^^^^^^^^^^^^^^^^^^^^^^^^^^^^^^^^^^^^^^^^^^^^^^^^^^^^^^^^^
  File "/home/airflow/.local/lib/python3.12/site-packages/airflow/models/taskinstance.py", line 733, in _execute_callable
    return ExecutionCallableRunner(
           ^^^^^^^^^^^^^^^^^^^^^^^^
  File "/home/airflow/.local/lib/python3.12/site-packages/airflow/utils/operator_helpers.py", line 252, in run
    return self.func(*args, **kwargs)
           ^^^^^^^^^^^^^^^^^^^^^^^^^^
  File "/home/airflow/.local/lib/python3.12/site-packages/airflow/models/baseoperator.py", line 417, in wrapper
    return func(self, *args, **kwargs)
           ^^^^^^^^^^^^^^^^^^^^^^^^^^^
  File "/home/airflow/.local/lib/python3.12/site-packages/airflow/operators/python.py", line 238, in execute
    return_value = self.execute_callable()
                   ^^^^^^^^^^^^^^^^^^^^^^^
  File "/home/airflow/.local/lib/python3.12/site-packages/airflow/operators/python.py", line 256, in execute_callable
    return runner.run(*self.op_args, **self.op_kwargs)
           ^^^^^^^^^^^^^^^^^^^^^^^^^^^^^^^^^^^^^^^^^^^
  File "/home/airflow/.local/lib/python3.12/site-packages/airflow/utils/operator_helpers.py", line 252, in run
    return self.func(*args, **kwargs)
           ^^^^^^^^^^^^^^^^^^^^^^^^^^
  File "/opt/airflow/dags/etl.py", line 21, in inserir_dados_historico
    conn = mysql.connector.connect(
           ^^^^^^^^^^^^^^^^^^^^^^^^
  File "/home/airflow/.local/lib/python3.12/site-packages/mysql/connector/pooling.py", line 322, in connect
    return CMySQLConnection(*args, **kwargs)
           ^^^^^^^^^^^^^^^^^^^^^^^^^^^^^^^^^
  File "/home/airflow/.local/lib/python3.12/site-packages/mysql/connector/connection_cext.py", line 151, in __init__
    self.connect(**kwargs)
  File "/home/airflow/.local/lib/python3.12/site-packages/mysql/connector/abstracts.py", line 1426, in connect
    self._open_connection()
  File "/home/airflow/.local/lib/python3.12/site-packages/mysql/connector/connection_cext.py", line 340, in _open_connection
    raise get_mysql_exception(
mysql.connector.errors.DatabaseError: 2003 (HY000): Can't connect to MySQL server on 'localhost:3306' (99)
[2024-11-08T22:46:30.257+0000] {logging_mixin.py:190} INFO - Task instance in failure state
[2024-11-08T22:46:30.258+0000] {logging_mixin.py:190} INFO - Task start:2024-11-08 22:46:29.054104+00:00 end:2024-11-08 22:46:30.257376+00:00 duration:1.203272
[2024-11-08T22:46:30.258+0000] {logging_mixin.py:190} INFO - Task:<Task(PythonOperator): inserir_dados_historico> dag:<DAG: api_inserir_dadosH> dagrun:<DagRun api_inserir_dadosH @ 2024-11-07 00:00:00+00:00: scheduled__2024-11-07T00:00:00+00:00, state:running, queued_at: 2024-11-08 22:46:23.202048+00:00. externally triggered: False>
[2024-11-08T22:46:30.258+0000] {logging_mixin.py:190} INFO - Failure caused by 2003 (HY000): Can't connect to MySQL server on 'localhost:3306' (99)
[2024-11-08T22:46:30.258+0000] {taskinstance.py:1225} INFO - Marking task as UP_FOR_RETRY. dag_id=api_inserir_dadosH, task_id=inserir_dados_historico, run_id=scheduled__2024-11-07T00:00:00+00:00, execution_date=20241107T000000, start_date=20241108T224629, end_date=20241108T224630
[2024-11-08T22:46:30.274+0000] {taskinstance.py:340} INFO - ::group::Post task execution logs
[2024-11-08T22:46:30.274+0000] {standard_task_runner.py:124} ERROR - Failed to execute job 5 for task inserir_dados_historico (2003 (HY000): Can't connect to MySQL server on 'localhost:3306' (99); 546)
Traceback (most recent call last):
  File "/home/airflow/.local/lib/python3.12/site-packages/mysql/connector/connection_cext.py", line 335, in _open_connection
    self._cmysql.connect(**cnx_kwargs)
_mysql_connector.MySQLInterfaceError: Can't connect to MySQL server on 'localhost:3306' (99)

The above exception was the direct cause of the following exception:

Traceback (most recent call last):
  File "/home/airflow/.local/lib/python3.12/site-packages/airflow/task/task_runner/standard_task_runner.py", line 117, in _start_by_fork
    ret = args.func(args, dag=self.dag)
          ^^^^^^^^^^^^^^^^^^^^^^^^^^^^^
  File "/home/airflow/.local/lib/python3.12/site-packages/airflow/cli/cli_config.py", line 49, in command
    return func(*args, **kwargs)
           ^^^^^^^^^^^^^^^^^^^^^
  File "/home/airflow/.local/lib/python3.12/site-packages/airflow/utils/cli.py", line 116, in wrapper
    return f(*args, **kwargs)
           ^^^^^^^^^^^^^^^^^^
  File "/home/airflow/.local/lib/python3.12/site-packages/airflow/cli/commands/task_command.py", line 483, in task_run
    task_return_code = _run_task_by_selected_method(args, _dag, ti)
                       ^^^^^^^^^^^^^^^^^^^^^^^^^^^^^^^^^^^^^^^^^^^^
  File "/home/airflow/.local/lib/python3.12/site-packages/airflow/cli/commands/task_command.py", line 256, in _run_task_by_selected_method
    return _run_raw_task(args, ti)
           ^^^^^^^^^^^^^^^^^^^^^^^
  File "/home/airflow/.local/lib/python3.12/site-packages/airflow/cli/commands/task_command.py", line 341, in _run_raw_task
    return ti._run_raw_task(
           ^^^^^^^^^^^^^^^^^
  File "/home/airflow/.local/lib/python3.12/site-packages/airflow/utils/session.py", line 97, in wrapper
    return func(*args, session=session, **kwargs)
           ^^^^^^^^^^^^^^^^^^^^^^^^^^^^^^^^^^^^^^
  File "/home/airflow/.local/lib/python3.12/site-packages/airflow/models/taskinstance.py", line 3005, in _run_raw_task
    return _run_raw_task(
           ^^^^^^^^^^^^^^
  File "/home/airflow/.local/lib/python3.12/site-packages/airflow/models/taskinstance.py", line 273, in _run_raw_task
    TaskInstance._execute_task_with_callbacks(
  File "/home/airflow/.local/lib/python3.12/site-packages/airflow/models/taskinstance.py", line 3159, in _execute_task_with_callbacks
    result = self._execute_task(context, task_orig)
             ^^^^^^^^^^^^^^^^^^^^^^^^^^^^^^^^^^^^^^
  File "/home/airflow/.local/lib/python3.12/site-packages/airflow/models/taskinstance.py", line 3183, in _execute_task
    return _execute_task(self, context, task_orig)
           ^^^^^^^^^^^^^^^^^^^^^^^^^^^^^^^^^^^^^^^
  File "/home/airflow/.local/lib/python3.12/site-packages/airflow/models/taskinstance.py", line 767, in _execute_task
    result = _execute_callable(context=context, **execute_callable_kwargs)
             ^^^^^^^^^^^^^^^^^^^^^^^^^^^^^^^^^^^^^^^^^^^^^^^^^^^^^^^^^^^^^
  File "/home/airflow/.local/lib/python3.12/site-packages/airflow/models/taskinstance.py", line 733, in _execute_callable
    return ExecutionCallableRunner(
           ^^^^^^^^^^^^^^^^^^^^^^^^
  File "/home/airflow/.local/lib/python3.12/site-packages/airflow/utils/operator_helpers.py", line 252, in run
    return self.func(*args, **kwargs)
           ^^^^^^^^^^^^^^^^^^^^^^^^^^
  File "/home/airflow/.local/lib/python3.12/site-packages/airflow/models/baseoperator.py", line 417, in wrapper
    return func(self, *args, **kwargs)
           ^^^^^^^^^^^^^^^^^^^^^^^^^^^
  File "/home/airflow/.local/lib/python3.12/site-packages/airflow/operators/python.py", line 238, in execute
    return_value = self.execute_callable()
                   ^^^^^^^^^^^^^^^^^^^^^^^
  File "/home/airflow/.local/lib/python3.12/site-packages/airflow/operators/python.py", line 256, in execute_callable
    return runner.run(*self.op_args, **self.op_kwargs)
           ^^^^^^^^^^^^^^^^^^^^^^^^^^^^^^^^^^^^^^^^^^^
  File "/home/airflow/.local/lib/python3.12/site-packages/airflow/utils/operator_helpers.py", line 252, in run
    return self.func(*args, **kwargs)
           ^^^^^^^^^^^^^^^^^^^^^^^^^^
  File "/opt/airflow/dags/etl.py", line 21, in inserir_dados_historico
    conn = mysql.connector.connect(
           ^^^^^^^^^^^^^^^^^^^^^^^^
  File "/home/airflow/.local/lib/python3.12/site-packages/mysql/connector/pooling.py", line 322, in connect
    return CMySQLConnection(*args, **kwargs)
           ^^^^^^^^^^^^^^^^^^^^^^^^^^^^^^^^^
  File "/home/airflow/.local/lib/python3.12/site-packages/mysql/connector/connection_cext.py", line 151, in __init__
    self.connect(**kwargs)
  File "/home/airflow/.local/lib/python3.12/site-packages/mysql/connector/abstracts.py", line 1426, in connect
    self._open_connection()
  File "/home/airflow/.local/lib/python3.12/site-packages/mysql/connector/connection_cext.py", line 340, in _open_connection
    raise get_mysql_exception(
mysql.connector.errors.DatabaseError: 2003 (HY000): Can't connect to MySQL server on 'localhost:3306' (99)
[2024-11-08T22:46:30.306+0000] {local_task_job_runner.py:266} INFO - Task exited with return code 1
[2024-11-08T22:46:30.326+0000] {taskinstance.py:3895} INFO - 0 downstream tasks scheduled from follow-on schedule check
[2024-11-08T22:46:30.327+0000] {local_task_job_runner.py:245} INFO - ::endgroup::
[2024-11-08T23:36:21.501+0000] {local_task_job_runner.py:123} INFO - ::group::Pre task execution logs
[2024-11-08T23:36:21.514+0000] {taskinstance.py:2613} INFO - Dependencies all met for dep_context=non-requeueable deps ti=<TaskInstance: api_inserir_dadosH.inserir_dados_historico scheduled__2024-11-07T00:00:00+00:00 [queued]>
[2024-11-08T23:36:21.521+0000] {taskinstance.py:2613} INFO - Dependencies all met for dep_context=requeueable deps ti=<TaskInstance: api_inserir_dadosH.inserir_dados_historico scheduled__2024-11-07T00:00:00+00:00 [queued]>
[2024-11-08T23:36:21.522+0000] {taskinstance.py:2866} INFO - Starting attempt 1 of 2
[2024-11-08T23:36:21.534+0000] {taskinstance.py:2889} INFO - Executing <Task(PythonOperator): inserir_dados_historico> on 2024-11-07 00:00:00+00:00
[2024-11-08T23:36:21.545+0000] {warnings.py:112} WARNING - /home/***/.local/lib/python3.12/site-packages/***/task/task_runner/standard_task_runner.py:70: DeprecationWarning: This process (pid=74) is multi-threaded, use of fork() may lead to deadlocks in the child.
  pid = os.fork()

[2024-11-08T23:36:21.547+0000] {standard_task_runner.py:72} INFO - Started process 76 to run task
[2024-11-08T23:36:21.547+0000] {standard_task_runner.py:104} INFO - Running: ['***', 'tasks', 'run', 'api_inserir_dadosH', 'inserir_dados_historico', 'scheduled__2024-11-07T00:00:00+00:00', '--job-id', '7', '--raw', '--subdir', 'DAGS_FOLDER/etl.py', '--cfg-path', '/tmp/tmpe97bjgn1']
[2024-11-08T23:36:21.548+0000] {standard_task_runner.py:105} INFO - Job 7: Subtask inserir_dados_historico
[2024-11-08T23:36:21.609+0000] {task_command.py:467} INFO - Running <TaskInstance: api_inserir_dadosH.inserir_dados_historico scheduled__2024-11-07T00:00:00+00:00 [running]> on host ee41a029bac5
[2024-11-08T23:36:21.674+0000] {taskinstance.py:3132} INFO - Exporting env vars: AIRFLOW_CTX_DAG_OWNER='***' AIRFLOW_CTX_DAG_ID='api_inserir_dadosH' AIRFLOW_CTX_TASK_ID='inserir_dados_historico' AIRFLOW_CTX_EXECUTION_DATE='2024-11-07T00:00:00+00:00' AIRFLOW_CTX_TRY_NUMBER='1' AIRFLOW_CTX_DAG_RUN_ID='scheduled__2024-11-07T00:00:00+00:00'
[2024-11-08T23:36:21.675+0000] {logging_mixin.py:190} INFO - Task instance is in running state
[2024-11-08T23:36:21.675+0000] {logging_mixin.py:190} INFO -  Previous state of the Task instance: queued
[2024-11-08T23:36:21.675+0000] {logging_mixin.py:190} INFO - Current task name:inserir_dados_historico state:running start_date:2024-11-08 23:36:21.514628+00:00
[2024-11-08T23:36:21.676+0000] {logging_mixin.py:190} INFO - Dag name:api_inserir_dadosH and current dag run status:running
[2024-11-08T23:36:21.676+0000] {taskinstance.py:731} INFO - ::endgroup::
[2024-11-08T23:36:21.847+0000] {taskinstance.py:3311} ERROR - Task failed with exception
Traceback (most recent call last):
  File "/home/airflow/.local/lib/python3.12/site-packages/mysql/connector/connection_cext.py", line 335, in _open_connection
    self._cmysql.connect(**cnx_kwargs)
_mysql_connector.MySQLInterfaceError: Can't connect to MySQL server on 'localhost:3306' (99)

The above exception was the direct cause of the following exception:

Traceback (most recent call last):
  File "/home/airflow/.local/lib/python3.12/site-packages/airflow/models/taskinstance.py", line 767, in _execute_task
    result = _execute_callable(context=context, **execute_callable_kwargs)
             ^^^^^^^^^^^^^^^^^^^^^^^^^^^^^^^^^^^^^^^^^^^^^^^^^^^^^^^^^^^^^
  File "/home/airflow/.local/lib/python3.12/site-packages/airflow/models/taskinstance.py", line 733, in _execute_callable
    return ExecutionCallableRunner(
           ^^^^^^^^^^^^^^^^^^^^^^^^
  File "/home/airflow/.local/lib/python3.12/site-packages/airflow/utils/operator_helpers.py", line 252, in run
    return self.func(*args, **kwargs)
           ^^^^^^^^^^^^^^^^^^^^^^^^^^
  File "/home/airflow/.local/lib/python3.12/site-packages/airflow/models/baseoperator.py", line 417, in wrapper
    return func(self, *args, **kwargs)
           ^^^^^^^^^^^^^^^^^^^^^^^^^^^
  File "/home/airflow/.local/lib/python3.12/site-packages/airflow/operators/python.py", line 238, in execute
    return_value = self.execute_callable()
                   ^^^^^^^^^^^^^^^^^^^^^^^
  File "/home/airflow/.local/lib/python3.12/site-packages/airflow/operators/python.py", line 256, in execute_callable
    return runner.run(*self.op_args, **self.op_kwargs)
           ^^^^^^^^^^^^^^^^^^^^^^^^^^^^^^^^^^^^^^^^^^^
  File "/home/airflow/.local/lib/python3.12/site-packages/airflow/utils/operator_helpers.py", line 252, in run
    return self.func(*args, **kwargs)
           ^^^^^^^^^^^^^^^^^^^^^^^^^^
  File "/opt/airflow/dags/etl.py", line 21, in inserir_dados_historico
    conn = mysql.connector.connect(
           ^^^^^^^^^^^^^^^^^^^^^^^^
  File "/home/airflow/.local/lib/python3.12/site-packages/mysql/connector/pooling.py", line 322, in connect
    return CMySQLConnection(*args, **kwargs)
           ^^^^^^^^^^^^^^^^^^^^^^^^^^^^^^^^^
  File "/home/airflow/.local/lib/python3.12/site-packages/mysql/connector/connection_cext.py", line 151, in __init__
    self.connect(**kwargs)
  File "/home/airflow/.local/lib/python3.12/site-packages/mysql/connector/abstracts.py", line 1426, in connect
    self._open_connection()
  File "/home/airflow/.local/lib/python3.12/site-packages/mysql/connector/connection_cext.py", line 340, in _open_connection
    raise get_mysql_exception(
mysql.connector.errors.DatabaseError: 2003 (HY000): Can't connect to MySQL server on 'localhost:3306' (99)
[2024-11-08T23:36:21.861+0000] {logging_mixin.py:190} INFO - Task instance in failure state
[2024-11-08T23:36:21.861+0000] {logging_mixin.py:190} INFO - Task start:2024-11-08 23:36:21.514628+00:00 end:2024-11-08 23:36:21.860708+00:00 duration:0.34608
[2024-11-08T23:36:21.861+0000] {logging_mixin.py:190} INFO - Task:<Task(PythonOperator): inserir_dados_historico> dag:<DAG: api_inserir_dadosH> dagrun:<DagRun api_inserir_dadosH @ 2024-11-07 00:00:00+00:00: scheduled__2024-11-07T00:00:00+00:00, state:running, queued_at: 2024-11-08 23:36:17.908162+00:00. externally triggered: False>
[2024-11-08T23:36:21.861+0000] {logging_mixin.py:190} INFO - Failure caused by 2003 (HY000): Can't connect to MySQL server on 'localhost:3306' (99)
[2024-11-08T23:36:21.862+0000] {taskinstance.py:1225} INFO - Marking task as UP_FOR_RETRY. dag_id=api_inserir_dadosH, task_id=inserir_dados_historico, run_id=scheduled__2024-11-07T00:00:00+00:00, execution_date=20241107T000000, start_date=20241108T233621, end_date=20241108T233621
[2024-11-08T23:36:21.876+0000] {taskinstance.py:340} INFO - ::group::Post task execution logs
[2024-11-08T23:36:21.877+0000] {standard_task_runner.py:124} ERROR - Failed to execute job 7 for task inserir_dados_historico (2003 (HY000): Can't connect to MySQL server on 'localhost:3306' (99); 76)
Traceback (most recent call last):
  File "/home/airflow/.local/lib/python3.12/site-packages/mysql/connector/connection_cext.py", line 335, in _open_connection
    self._cmysql.connect(**cnx_kwargs)
_mysql_connector.MySQLInterfaceError: Can't connect to MySQL server on 'localhost:3306' (99)

The above exception was the direct cause of the following exception:

Traceback (most recent call last):
  File "/home/airflow/.local/lib/python3.12/site-packages/airflow/task/task_runner/standard_task_runner.py", line 117, in _start_by_fork
    ret = args.func(args, dag=self.dag)
          ^^^^^^^^^^^^^^^^^^^^^^^^^^^^^
  File "/home/airflow/.local/lib/python3.12/site-packages/airflow/cli/cli_config.py", line 49, in command
    return func(*args, **kwargs)
           ^^^^^^^^^^^^^^^^^^^^^
  File "/home/airflow/.local/lib/python3.12/site-packages/airflow/utils/cli.py", line 116, in wrapper
    return f(*args, **kwargs)
           ^^^^^^^^^^^^^^^^^^
  File "/home/airflow/.local/lib/python3.12/site-packages/airflow/cli/commands/task_command.py", line 483, in task_run
    task_return_code = _run_task_by_selected_method(args, _dag, ti)
                       ^^^^^^^^^^^^^^^^^^^^^^^^^^^^^^^^^^^^^^^^^^^^
  File "/home/airflow/.local/lib/python3.12/site-packages/airflow/cli/commands/task_command.py", line 256, in _run_task_by_selected_method
    return _run_raw_task(args, ti)
           ^^^^^^^^^^^^^^^^^^^^^^^
  File "/home/airflow/.local/lib/python3.12/site-packages/airflow/cli/commands/task_command.py", line 341, in _run_raw_task
    return ti._run_raw_task(
           ^^^^^^^^^^^^^^^^^
  File "/home/airflow/.local/lib/python3.12/site-packages/airflow/utils/session.py", line 97, in wrapper
    return func(*args, session=session, **kwargs)
           ^^^^^^^^^^^^^^^^^^^^^^^^^^^^^^^^^^^^^^
  File "/home/airflow/.local/lib/python3.12/site-packages/airflow/models/taskinstance.py", line 3005, in _run_raw_task
    return _run_raw_task(
           ^^^^^^^^^^^^^^
  File "/home/airflow/.local/lib/python3.12/site-packages/airflow/models/taskinstance.py", line 273, in _run_raw_task
    TaskInstance._execute_task_with_callbacks(
  File "/home/airflow/.local/lib/python3.12/site-packages/airflow/models/taskinstance.py", line 3159, in _execute_task_with_callbacks
    result = self._execute_task(context, task_orig)
             ^^^^^^^^^^^^^^^^^^^^^^^^^^^^^^^^^^^^^^
  File "/home/airflow/.local/lib/python3.12/site-packages/airflow/models/taskinstance.py", line 3183, in _execute_task
    return _execute_task(self, context, task_orig)
           ^^^^^^^^^^^^^^^^^^^^^^^^^^^^^^^^^^^^^^^
  File "/home/airflow/.local/lib/python3.12/site-packages/airflow/models/taskinstance.py", line 767, in _execute_task
    result = _execute_callable(context=context, **execute_callable_kwargs)
             ^^^^^^^^^^^^^^^^^^^^^^^^^^^^^^^^^^^^^^^^^^^^^^^^^^^^^^^^^^^^^
  File "/home/airflow/.local/lib/python3.12/site-packages/airflow/models/taskinstance.py", line 733, in _execute_callable
    return ExecutionCallableRunner(
           ^^^^^^^^^^^^^^^^^^^^^^^^
  File "/home/airflow/.local/lib/python3.12/site-packages/airflow/utils/operator_helpers.py", line 252, in run
    return self.func(*args, **kwargs)
           ^^^^^^^^^^^^^^^^^^^^^^^^^^
  File "/home/airflow/.local/lib/python3.12/site-packages/airflow/models/baseoperator.py", line 417, in wrapper
    return func(self, *args, **kwargs)
           ^^^^^^^^^^^^^^^^^^^^^^^^^^^
  File "/home/airflow/.local/lib/python3.12/site-packages/airflow/operators/python.py", line 238, in execute
    return_value = self.execute_callable()
                   ^^^^^^^^^^^^^^^^^^^^^^^
  File "/home/airflow/.local/lib/python3.12/site-packages/airflow/operators/python.py", line 256, in execute_callable
    return runner.run(*self.op_args, **self.op_kwargs)
           ^^^^^^^^^^^^^^^^^^^^^^^^^^^^^^^^^^^^^^^^^^^
  File "/home/airflow/.local/lib/python3.12/site-packages/airflow/utils/operator_helpers.py", line 252, in run
    return self.func(*args, **kwargs)
           ^^^^^^^^^^^^^^^^^^^^^^^^^^
  File "/opt/airflow/dags/etl.py", line 21, in inserir_dados_historico
    conn = mysql.connector.connect(
           ^^^^^^^^^^^^^^^^^^^^^^^^
  File "/home/airflow/.local/lib/python3.12/site-packages/mysql/connector/pooling.py", line 322, in connect
    return CMySQLConnection(*args, **kwargs)
           ^^^^^^^^^^^^^^^^^^^^^^^^^^^^^^^^^
  File "/home/airflow/.local/lib/python3.12/site-packages/mysql/connector/connection_cext.py", line 151, in __init__
    self.connect(**kwargs)
  File "/home/airflow/.local/lib/python3.12/site-packages/mysql/connector/abstracts.py", line 1426, in connect
    self._open_connection()
  File "/home/airflow/.local/lib/python3.12/site-packages/mysql/connector/connection_cext.py", line 340, in _open_connection
    raise get_mysql_exception(
mysql.connector.errors.DatabaseError: 2003 (HY000): Can't connect to MySQL server on 'localhost:3306' (99)
[2024-11-08T23:36:21.922+0000] {local_task_job_runner.py:266} INFO - Task exited with return code 1
[2024-11-08T23:36:21.942+0000] {taskinstance.py:3895} INFO - 0 downstream tasks scheduled from follow-on schedule check
[2024-11-08T23:36:21.943+0000] {local_task_job_runner.py:245} INFO - ::endgroup::
